Workbook

Sheet 사용법
B2: 대출 이자 계산기 — 사용법
B4: 1. [계산기] 시트의 노란 칸(파란 글씨) 5개만 바꾸세요. 나머지는 자동 계산됩니다.
B5: · 대출 원금(원) · 연 이자율 · 대출 기간(개월, 최대 480) · 상환 방식(목록에서 선택) · 금리 변동 폭
B6: 2. [계산기] 아래 "금리가 바뀌면?" 표에서 금리가 오르내릴 때 월 상환액·총이자 차이를 비교할 수 있습니다.
B7: 3. [상환스케줄] 시트에서 매달 이자·원금·남은 잔액을 확인할 수 있습니다.
B9: 상환 방식 설명
B10: · 원리금균등: 매달 같은 금액(이자+원금)을 냅니다. 초반엔 이자 비중이 큽니다.
B11: · 원금균등: 매달 같은 원금을 갚아 상환액이 점점 줄어듭니다. 세 방식 중 총이자가 가장 적습니다.
B12: · 만기일시: 매달 이자만 내고 마지막 달에 원금을 한 번에 갚습니다. 세 방식 중 총이자가 가장 많습니다.
B14: 꼭 읽어 주세요
B15: · 월 단위 단순 계산(연 이자율 ÷ 12)입니다. 실제 은행 이자는 일할 계산·우대금리·수수료 등에 따라 다를 수 있습니다.
B16: · 변동금리 대출은 계약서의 금리 변동 주기·기준금리(코픽스 등)에 따라 실제 적용 시점이 다릅니다.
... B19: 제작: 에이팜의 이야기 보따리 (blog.naver.com/iwmyd99) · Excel·구글 스프레드시트에서 동작합니다.

Sheet 계산기
B2: 대출 이자 계산기
B3: 노란 칸만 바꾸세요 (예시 값이 들어 있습니다)
B5: 대출 원금 | C5: 300000000 | D5: 예시 값. 본인 대출 원금으로 바꾸세요.
B6: 연 이자율 | C6: 0.045 | D6: 예시 값. 연 4.5%는 4.5% 로 입력.
B7: 대출 기간(개월) | C7: 360 | D7: 1~480개월. 30년 = 360.
B8: 상환 방식 | C8: 원리금균등 | D8: 목록에서 선택: 원리금균등 / 원금균등 / 만기일시
B9: 금리 변동 폭 | C9: 0.0025 | D9: 아래 비교표의 한 칸 간격. 0.25%p = 0.25%.
B11: 계산 결과
B12: 월 이자율 | C12: =C6/12
B13: 첫 달 상환액 | C13: ='상환스케줄'!F6
B14: 마지막 달 상환액 | C14: =INDEX('상환스케줄'!F6:F485,C7)
B15: 총 이자 | C15: =SUM('상환스케줄'!D6:D485)
B16: 총 상환액 | C16: =C5+C15
B18: 금리가 바뀌면? (상환 방식별 비교)
B19: 금리 변동 | C19: 적용 연 이자율 | D19: 원리금균등 월 상환액 | E19: 원금균등 첫 달 상환액 | F19: 만기일시 월 이자 | G19: 총이자 차이(선택 방식)
B20: =-2*$C$9 | C20: =MAX(0,$C$6+B20) | D20: =IF(C20=0,$C$5/$C$7,PMT(C20/12,$C$7,-$C$5)) | E20: =$C$5/$C$7+$C$5*C20/12 | F20: =$C$5*C20/12 | G20: =IF($C$8="원리금균등",IF(C20=0,0,PMT(C20/12,$C$7,-$C$5)*$C$7-$C$5),IF($C$8="원금균등",$C$5*C20/12*($C$7+1)/2,$C$5*C20/12*$C$7))-IF($C$8="원리금균등",IF($C$22=0,0,PMT($C$22/12,$C$7,-$C$5)*$C$7-$C$5),IF($C$8="원금균등",$C$5*$C$22/12*($C$7+1)/2,$C$5*$C$22/12*$C$7))
B21: =-1*$C$9 | C21: =MAX(0,$C$6+B21) | D21: =IF(C21=0,$C$5/$C$7,PMT(C21/12,$C$7,-$C$5)) | E21: =$C$5/$C$7+$C$5*C21/12 | F21: =$C$5*C21/12 | G21: =IF($C$8="원리금균등",IF(C21=0,0,PMT(C21/12,$C$7,-$C$5)*$C$7-$C$5),IF($C$8="원금균등",$C$5*C21/12*($C$7+1)/2,$C$5*C21/12*$C$7))-IF($C$8="원리금균등",IF($C$22=0,0,PMT($C$22/12,$C$7,-$C$5)*$C$7-$C$5),IF($C$8="원금균등",$C$5*$C$22/12*($C$7+1)/2,$C$5*$C$22/12*$C$7))
B22: =0*$C$9 | C22: =MAX(0,$C$6+B22) | D22: =IF(C22=0,$C$5/$C$7,PMT(C22/12,$C$7,-$C$5)) | E22: =$C$5/$C$7+$C$5*C22/12 | F22: =$C$5*C22/12 | G22: =IF($C$8="원리금균등",IF(C22=0,0,PMT(C22/12,$C$7,-$C$5)*$C$7-$C$5),IF($C$8="원금균등",$C$5*C22/12*($C$7+1)/2,$C$5*C22/12*$C$7))-IF($C$8="원리금균등",IF($C$22=0,0,PMT($C$22/12,$C$7,-$C$5)*$C$7-$C$5),IF($C$8="원금균등",$C$5*$C$22/12*($C$7+1)/2,$C$5*$C$22/12*$C$7))
B23: =1*$C$9 | C23: =MAX(0,$C$6+B23) | D23: =IF(C23=0,$C$5/$C$7,PMT(C23/12,$C$7,-$C$5)) | E23: =$C$5/$C$7+$C$5*C23/12 | F23: =$C$5*C23/12 | G23: =IF($C$8="원리금균등",IF(C23=0,0,PMT(C23/12,$C$7,-$C$5)*$C$7-$C$5),IF($C$8="원금균등",$C$5*C23/12*($C$7+1)/2,$C$5*C23/12*$C$7))-IF($C$8="원리금균등",IF($C$22=0,0,PMT($C$22/12,$C$7,-$C$5)*$C$7-$C$5),IF($C$8="원금균등",$C$5*$C$22/12*($C$7+1)/2,$C$5*$C$22/12*$C$7))
B24: =2*$C$9 | C24: =MAX(0,$C$6+B24) | D24: =IF(C24=0,$C$5/$C$7,PMT(C24/12,$C$7,-$C$5)) | E24: =$C$5/$C$7+$C$5*C24/12 | F24: =$C$5*C24/12 | G24: =IF($C$8="원리금균등",IF(C24=0,0,PMT(C24/12,$C$7,-$C$5)*$C$7-$C$5),IF($C$8="원금균등",$C$5*C24/12*($C$7+1)/2,$C$5*C24/12*$C$7))-IF($C$8="원리금균등",IF($C$22=0,0,PMT($C$22/12,$C$7,-$C$5)*$C$7-$C$5),IF($C$8="원금균등",$C$5*$C$22/12*($C$7+1)/2,$C$5*$C$22/12*$C$7))
B26: ※ 비교표는 대출 전 기간에 같은 금리가 적용된다고 가정한 단순 계산입니다.
B27: ※ 검산: "현재" 행의 총이자 차이는 항상 "-"(0원)입니다.

Sheet 상환스케줄
B2: 월별 상환 스케줄
B3: ='계산기'!C8&" · 원금 "&TEXT('계산기'!C5,"#,##0")&"원 · 연 "&TEXT('계산기'!C6,"0.00%")&" · "&'계산기'!C7&"개월"
B5: 회차 | C5: 기초 잔액 | D5: 이자 | E5: 원금 | F5: 상환액 | G5: 기말 잔액
B6: =IF(1<='계산기'!$C$7,1,"") | C6: =IF(B6="","",'계산기'!$C$5) | D6: =IF(B6="","",C6*'계산기'!$C$12) | E6: =IF(B6="","",IF(B6='계산기'!$C$7,C6,IF('계산기'!$C$8="원리금균등",IF('계산기'!$C$12=0,'계산기'!$C$5/'계산기'!$C$7,PMT('계산기'!$C$12,'계산기'!$C$7,-'계산기'!$C$5))-D6,IF('계산기'!$C$8="원금균등",'계산기'!$C$5/'계산기'!$C$7,0)))) | F6: =IF(B6="","",D6+E6) | G6: =IF(B6="","",C6-E6)
B7: =IF(2<='계산기'!$C$7,2,"") | C7: =IF(B7="","",G6) | D7: =IF(B7="","",C7*'계산기'!$C$12) | E7: =IF(B7="","",IF(B7='계산기'!$C$7,C7,IF('계산기'!$C$8="원리금균등",IF('계산기'!$C$12=0,'계산기'!$C$5/'계산기'!$C$7,PMT('계산기'!$C$12,'계산기'!$C$7,-'계산기'!$C$5))-D7,IF('계산기'!$C$8="원금균등",'계산기'!$C$5/'계산기'!$C$7,0)))) | F7: =IF(B7="","",D7+E7) | G7: =IF(B7="","",C7-E7)
B8: =IF(3<='계산기'!$C$7,3,"") | C8: =IF(B8="","",G7) | D8: =IF(B8="","",C8*'계산기'!$C$12) | E8: =IF(B8="","",IF(B8='계산기'!$C$7,C8,IF('계산기'!$C$8="원리금균등",IF('계산기'!$C$12=0,'계산기'!$C$5/'계산기'!$C$7,PMT('계산기'!$C$12,'계산기'!$C$7,-'계산기'!$C$5))-D8,IF('계산기'!$C$8="원금균등",'계산기'!$C$5/'계산기'!$C$7,0)))) | F8: =IF(B8="","",D8+E8) | G8: =IF(B8="","",C8-E8)
B9: =IF(4<='계산기'!$C$7,4,"") | C9: =IF(B9="","",G8) | D9: =IF(B9="","",C9*'계산기'!$C$12) | E9: =IF(B9="","",IF(B9='계산기'!$C$7,C9,IF('계산기'!$C$8="원리금균등",IF('계산기'!$C$12=0,'계산기'!$C$5/'계산기'!$C$7,PMT('계산기'!$C$12,'계산기'!$C$7,-'계산기'!$C$5))-D9,IF('계산기'!$C$8="원금균등",'계산기'!$C$5/'계산기'!$C$7,0)))) | F9: =IF(B9="","",D9+E9) | G9: =IF(B9="","",C9-E9)
B10: =IF(5<='계산기'!$C$7,5,"") | C10: =IF(B10="","",G9) | D10: =IF(B10="","",C10*'계산기'!$C$12) | E10: =IF(B10="","",IF(B10='계산기'!$C$7,C10,IF('계산기'!$C$8="원리금균등",IF('계산기'!$C$12=0,'계산기'!$C$5/'계산기'!$C$7,PMT('계산기'!$C$12,'계산기'!$C$7,-'계산기'!$C$5))-D10,IF('계산기'!$C$8="원금균등",'계산기'!$C$5/'계산기'!$C$7,0)))) | F10: =IF(B10="","",D10+E10) | G10: =IF(B10="","",C10-E10)
B11: =IF(6<='계산기'!$C$7,6,"") | C11: =IF(B11="","",G10) | D11: =IF(B11="","",C11*'계산기'!$C$12) | E11: =IF(B11="","",IF(B11='계산기'!$C$7,C11,IF('계산기'!$C$8="원리금균등",IF('계산기'!$C$12=0,'계산기'!$C$5/'계산기'!$C$7,PMT('계산기'!$C$12,'계산기'!$C$7,-'계산기'!$C$5))-D11,IF('계산기'!$C$8="원금균등",'계산기'!$C$5/'계산기'!$C$7,0)))) | F11: =IF(B11="","",D11+E11) | G11: =IF(B11="","",C11-E11)
B12: =IF(7<='계산기'!$C$7,7,"") | C12: =IF(B12="","",G11) | D12: =IF(B12="","",C12*'계산기'!$C$12) | E12: =IF(B12="","",IF(B12='계산기'!$C$7,C12,IF('계산기'!$C$8="원리금균등",IF('계산기'!$C$12=0,'계산기'!$C$5/'계산기'!$C$7,PMT('계산기'!$C$12,'계산기'!$C$7,-'계산기'!$C$5))-D12,IF('계산기'!$C$8="원금균등",'계산기'!$C$5/'계산기'!$C$7,0)))) | F12: =IF(B12="","",D12+E12) | G12: =IF(B12="","",C12-E12)
B13: =IF(8<='계산기'!$C$7,8,"") | C13: =IF(B13="","",G12) | D13: =IF(B13="","",C13*'계산기'!$C$12) | E13: =IF(B13="","",IF(B13='계산기'!$C$7,C13,IF('계산기'!$C$8="원리금균등",IF('계산기'!$C$12=0,'계산기'!$C$5/'계산기'!$C$7,PMT('계산기'!$C$12,'계산기'!$C$7,-'계산기'!$C$5))-D13,IF('계산기'!$C$8="원금균등",'계산기'!$C$5/'계산기'!$C$7,0)))) | F13: =IF(B13="","",D13+E13) | G13: =IF(B13="","",C13-E13)
B14: =IF(9<='계산기'!$C$7,9,"") | C14: =IF(B14="","",G13) | D14: =IF(B14="","",C14*'계산기'!$C$12) | E14: =IF(B14="","",IF(B14='계산기'!$C$7,C14,IF('계산기'!$C$8="원리금균등",IF('계산기'!$C$12=0,'계산기'!$C$5/'계산기'!$C$7,PMT('계산기'!$C$12,'계산기'!$C$7,-'계산기'!$C$5))-D14,IF('계산기'!$C$8="원금균등",'계산기'!$C$5/'계산기'!$C$7,0)))) | F14: =IF(B14="","",D14+E14) | G14: =IF(B14="","",C14-E14)
B15: =IF(10<='계산기'!$C$7,10,"") | C15: =IF(B15="","",G14) | D15: =IF(B15="","",C15*'계산기'!$C$12) | E15: =IF(B15="","",IF(B15='계산기'!$C$7,C15,IF('계산기'!$C$8="원리금균등",IF('계산기'!$C$12=0,'계산기'!$C$5/'계산기'!$C$7,PMT('계산기'!$C$12,'계산기'!$C$7,-'계산기'!$C$5))-D15,IF('계산기'!$C$8="원금균등",'계산기'!$C$5/'계산기'!$C$7,0)))) | F15: =IF(B15="","",D15+E15) | G15: =IF(B15="","",C15-E15)
B16: =IF(11<='계산기'!$C$7,11,"") | C16: =IF(B16="","",G15) | D16: =IF(B16="","",C16*'계산기'!$C$12) | E16: =IF(B16="","",IF(B16='계산기'!$C$7,C16,IF('계산기'!$C$8="원리금균등",IF('계산기'!$C$12=0,'계산기'!$C$5/'계산기'!$C$7,PMT('계산기'!$C$12,'계산기'!$C$7,-'계산기'!$C$5))-D16,IF('계산기'!$C$8="원금균등",'계산기'!$C$5/'계산기'!$C$7,0)))) | F16: =IF(B16="","",D16+E16) | G16: =IF(B16="","",C16-E16)
B17: =IF(12<='계산기'!$C$7,12,"") | C17: =IF(B17="","",G16) | D17: =IF(B17="","",C17*'계산기'!$C$12) | E17: =IF(B17="","",IF(B17='계산기'!$C$7,C17,IF('계산기'!$C$8="원리금균등",IF('계산기'!$C$12=0,'계산기'!$C$5/'계산기'!$C$7,PMT('계산기'!$C$12,'계산기'!$C$7,-'계산기'!$C$5))-D17,IF('계산기'!$C$8="원금균등",'계산기'!$C$5/'계산기'!$C$7,0)))) | F17: =IF(B17="","",D17+E17) | G17: =IF(B17="","",C17-E17)
B18: =IF(13<='계산기'!$C$7,13,"") | C18: =IF(B18="","",G17) | D18: =IF(B18="","",C18*'계산기'!$C$12) | E18: =IF(B18="","",IF(B18='계산기'!$C$7,C18,IF('계산기'!$C$8="원리금균등",IF('계산기'!$C$12=0,'계산기'!$C$5/'계산기'!$C$7,PMT('계산기'!$C$12,'계산기'!$C$7,-'계산기'!$C$5))-D18,IF('계산기'!$C$8="원금균등",'계산기'!$C$5/'계산기'!$C$7,0)))) | F18: =IF(B18="","",D18+E18) | G18: =IF(B18="","",C18-E18)
B19: =IF(14<='계산기'!$C$7,14,"") | C19: =IF(B19="","",G18) | D19: =IF(B19="","",C19*'계산기'!$C$12) | E19: =IF(B19="","",IF(B19='계산기'!$C$7,C19,IF('계산기'!$C$8="원리금균등",IF('계산기'!$C$12=0,'계산기'!$C$5/'계산기'!$C$7,PMT('계산기'!$C$12,'계산기'!$C$7,-'계산기'!$C$5))-D19,IF('계산기'!$C$8="원금균등",'계산기'!$C$5/'계산기'!$C$7,0)))) | F19: =IF(B19="","",D19+E19) | G19: =IF(B19="","",C19-E19)
B20: =IF(15<='계산기'!$C$7,15,"") | C20: =IF(B20="","",G19) | D20: =IF(B20="","",C20*'계산기'!$C$12) | E20: =IF(B20="","",IF(B20='계산기'!$C$7,C20,IF('계산기'!$C$8="원리금균등",IF('계산기'!$C$12=0,'계산기'!$C$5/'계산기'!$C$7,PMT('계산기'!$C$12,'계산기'!$C$7,-'계산기'!$C$5))-D20,IF('계산기'!$C$8="원금균등",'계산기'!$C$5/'계산기'!$C$7,0)))) | F20: =IF(B20="","",D20+E20) | G20: =IF(B20="","",C20-E20)
B21: =IF(16<='계산기'!$C$7,16,"") | C21: =IF(B21="","",G20) | D21: =IF(B21="","",C21*'계산기'!$C$12) | E21: =IF(B21="","",IF(B21='계산기'!$C$7,C21,IF('계산기'!$C$8="원리금균등",IF('계산기'!$C$12=0,'계산기'!$C$5/'계산기'!$C$7,PMT('계산기'!$C$12,'계산기'!$C$7,-'계산기'!$C$5))-D21,IF('계산기'!$C$8="원금균등",'계산기'!$C$5/'계산기'!$C$7,0)))) | F21: =IF(B21="","",D21+E21) | G21: =IF(B21="","",C21-E21)
B22: =IF(17<='계산기'!$C$7,17,"") | C22: =IF(B22="","",G21) | D22: =IF(B22="","",C22*'계산기'!$C$12) | E22: =IF(B22="","",IF(B22='계산기'!$C$7,C22,IF('계산기'!$C$8="원리금균등",IF('계산기'!$C$12=0,'계산기'!$C$5/'계산기'!$C$7,PMT('계산기'!$C$12,'계산기'!$C$7,-'계산기'!$C$5))-D22,IF('계산기'!$C$8="원금균등",'계산기'!$C$5/'계산기'!$C$7,0)))) | F22: =IF(B22="","",D22+E22) | G22: =IF(B22="","",C22-E22)
B23: =IF(18<='계산기'!$C$7,18,"") | C23: =IF(B23="","",G22) | D23: =IF(B23="","",C23*'계산기'!$C$12) | E23: =IF(B23="","",IF(B23='계산기'!$C$7,C23,IF('계산기'!$C$8="원리금균등",IF('계산기'!$C$12=0,'계산기'!$C$5/'계산기'!$C$7,PMT('계산기'!$C$12,'계산기'!$C$7,-'계산기'!$C$5))-D23,IF('계산기'!$C$8="원금균등",'계산기'!$C$5/'계산기'!$C$7,0)))) | F23: =IF(B23="","",D23+E23) | G23: =IF(B23="","",C23-E23)
B24: =IF(19<='계산기'!$C$7,19,"") | C24: =IF(B24="","",G23) | D24: =IF(B24="","",C24*'계산기'!$C$12) | E24: =IF(B24="","",IF(B24='계산기'!$C$7,C24,IF('계산기'!$C$8="원리금균등",IF('계산기'!$C$12=0,'계산기'!$C$5/'계산기'!$C$7,PMT('계산기'!$C$12,'계산기'!$C$7,-'계산기'!$C$5))-D24,IF('계산기'!$C$8="원금균등",'계산기'!$C$5/'계산기'!$C$7,0)))) | F24: =IF(B24="","",D24+E24) | G24: =IF(B24="","",C24-E24)
B25: =IF(20<='계산기'!$C$7,20,"") | C25: =IF(B25="","",G24) | D25: =IF(B25="","",C25*'계산기'!$C$12) | E25: =IF(B25="","",IF(B25='계산기'!$C$7,C25,IF('계산기'!$C$8="원리금균등",IF('계산기'!$C$12=0,'계산기'!$C$5/'계산기'!$C$7,PMT('계산기'!$C$12,'계산기'!$C$7,-'계산기'!$C$5))-D25,IF('계산기'!$C$8="원금균등",'계산기'!$C$5/'계산기'!$C$7,0)))) | F25: =IF(B25="","",D25+E25) | G25: =IF(B25="","",C25-E25)
B26: =IF(21<='계산기'!$C$7,21,"") | C26: =IF(B26="","",G25) | D26: =IF(B26="","",C26*'계산기'!$C$12) | E26: =IF(B26="","",IF(B26='계산기'!$C$7,C26,IF('계산기'!$C$8="원리금균등",IF('계산기'!$C$12=0,'계산기'!$C$5/'계산기'!$C$7,PMT('계산기'!$C$12,'계산기'!$C$7,-'계산기'!$C$5))-D26,IF('계산기'!$C$8="원금균등",'계산기'!$C$5/'계산기'!$C$7,0)))) | F26: =IF(B26="","",D26+E26) | G26: =IF(B26="","",C26-E26)
B27: =IF(22<='계산기'!$C$7,22,"") | C27: =IF(B27="","",G26) | D27: =IF(B27="","",C27*'계산기'!$C$12) | E27: =IF(B27="","",IF(B27='계산기'!$C$7,C27,IF('계산기'!$C$8="원리금균등",IF('계산기'!$C$12=0,'계산기'!$C$5/'계산기'!$C$7,PMT('계산기'!$C$12,'계산기'!$C$7,-'계산기'!$C$5))-D27,IF('계산기'!$C$8="원금균등",'계산기'!$C$5/'계산기'!$C$7,0)))) | F27: =IF(B27="","",D27+E27) | G27: =IF(B27="","",C27-E27)
B28: =IF(23<='계산기'!$C$7,23,"") | C28: =IF(B28="","",G27) | D28: =IF(B28="","",C28*'계산기'!$C$12) | E28: =IF(B28="","",IF(B28='계산기'!$C$7,C28,IF('계산기'!$C$8="원리금균등",IF('계산기'!$C$12=0,'계산기'!$C$5/'계산기'!$C$7,PMT('계산기'!$C$12,'계산기'!$C$7,-'계산기'!$C$5))-D28,IF('계산기'!$C$8="원금균등",'계산기'!$C$5/'계산기'!$C$7,0)))) | F28: =IF(B28="","",D28+E28) | G28: =IF(B28="","",C28-E28)
B29: =IF(24<='계산기'!$C$7,24,"") | C29: =IF(B29="","",G28) | D29: =IF(B29="","",C29*'계산기'!$C$12) | E29: =IF(B29="","",IF(B29='계산기'!$C$7,C29,IF('계산기'!$C$8="원리금균등",IF('계산기'!$C$12=0,'계산기'!$C$5/'계산기'!$C$7,PMT('계산기'!$C$12,'계산기'!$C$7,-'계산기'!$C$5))-D29,IF('계산기'!$C$8="원금균등",'계산기'!$C$5/'계산기'!$C$7,0)))) | F29: =IF(B29="","",D29+E29) | G29: =IF(B29="","",C29-E29)
B30: =IF(25<='계산기'!$C$7,25,"") | C30: =IF(B30="","",G29) | D30: =IF(B30="","",C30*'계산기'!$C$12) | E30: =IF(B30="","",IF(B30='계산기'!$C$7,C30,IF('계산기'!$C$8="원리금균등",IF('계산기'!$C$12=0,'계산기'!$C$5/'계산기'!$C$7,PMT('계산기'!$C$12,'계산기'!$C$7,-'계산기'!$C$5))-D30,IF('계산기'!$C$8="원금균등",'계산기'!$C$5/'계산기'!$C$7,0)))) | F30: =IF(B30="","",D30+E30) | G30: =IF(B30="","",C30-E30)
B31: =IF(26<='계산기'!$C$7,26,"") | C31: =IF(B31="","",G30) | D31: =IF(B31="","",C31*'계산기'!$C$12) | E31: =IF(B31="","",IF(B31='계산기'!$C$7,C31,IF('계산기'!$C$8="원리금균등",IF('계산기'!$C$12=0,'계산기'!$C$5/'계산기'!$C$7,PMT('계산기'!$C$12,'계산기'!$C$7,-'계산기'!$C$5))-D31,IF('계산기'!$C$8="원금균등",'계산기'!$C$5/'계산기'!$C$7,0)))) | F31: =IF(B31="","",D31+E31) | G31: =IF(B31="","",C31-E31)
B32: =IF(27<='계산기'!$C$7,27,"") | C32: =IF(B32="","",G31) | D32: =IF(B32="","",C32*'계산기'!$C$12) | E32: =IF(B32="","",IF(B32='계산기'!$C$7,C32,IF('계산기'!$C$8="원리금균등",IF('계산기'!$C$12=0,'계산기'!$C$5/'계산기'!$C$7,PMT('계산기'!$C$12,'계산기'!$C$7,-'계산기'!$C$5))-D32,IF('계산기'!$C$8="원금균등",'계산기'!$C$5/'계산기'!$C$7,0)))) | F32: =IF(B32="","",D32+E32) | G32: =IF(B32="","",C32-E32)
B33: =IF(28<='계산기'!$C$7,28,"") | C33: =IF(B33="","",G32) | D33: =IF(B33="","",C33*'계산기'!$C$12) | E33: =IF(B33="","",IF(B33='계산기'!$C$7,C33,IF('계산기'!$C$8="원리금균등",IF('계산기'!$C$12=0,'계산기'!$C$5/'계산기'!$C$7,PMT('계산기'!$C$12,'계산기'!$C$7,-'계산기'!$C$5))-D33,IF('계산기'!$C$8="원금균등",'계산기'!$C$5/'계산기'!$C$7,0)))) | F33: =IF(B33="","",D33+E33) | G33: =IF(B33="","",C33-E33)
B34: =IF(29<='계산기'!$C$7,29,"") | C34: =IF(B34="","",G33) | D34: =IF(B34="","",C34*'계산기'!$C$12) | E34: =IF(B34="","",IF(B34='계산기'!$C$7,C34,IF('계산기'!$C$8="원리금균등",IF('계산기'!$C$12=0,'계산기'!$C$5/'계산기'!$C$7,PMT('계산기'!$C$12,'계산기'!$C$7,-'계산기'!$C$5))-D34,IF('계산기'!$C$8="원금균등",'계산기'!$C$5/'계산기'!$C$7,0)))) | F34: =IF(B34="","",D34+E34) | G34: =IF(B34="","",C34-E34)
B35: =IF(30<='계산기'!$C$7,30,"") | C35: =IF(B35="","",G34) | D35: =IF(B35="","",C35*'계산기'!$C$12) | E35: =IF(B35="","",IF(B35='계산기'!$C$7,C35,IF('계산기'!$C$8="원리금균등",IF('계산기'!$C$12=0,'계산기'!$C$5/'계산기'!$C$7,PMT('계산기'!$C$12,'계산기'!$C$7,-'계산기'!$C$5))-D35,IF('계산기'!$C$8="원금균등",'계산기'!$C$5/'계산기'!$C$7,0)))) | F35: =IF(B35="","",D35+E35) | G35: =IF(B35="","",C35-E35)
B36: =IF(31<='계산기'!$C$7,31,"") | C36: =IF(B36="","",G35) | D36: =IF(B36="","",C36*'계산기'!$C$12) | E36: =IF(B36="","",IF(B36='계산기'!$C$7,C36,IF('계산기'!$C$8="원리금균등",IF('계산기'!$C$12=0,'계산기'!$C$5/'계산기'!$C$7,PMT('계산기'!$C$12,'계산기'!$C$7,-'계산기'!$C$5))-D36,IF('계산기'!$C$8="원금균등",'계산기'!$C$5/'계산기'!$C$7,0)))) | F36: =IF(B36="","",D36+E36) | G36: =IF(B36="","",C36-E36)
B37: =IF(32<='계산기'!$C$7,32,"") | C37: =IF(B37="","",G36) | D37: =IF(B37="","",C37*'계산기'!$C$12) | E37: =IF(B37="","",IF(B37='계산기'!$C$7,C37,IF('계산기'!$C$8="원리금균등",IF('계산기'!$C$12=0,'계산기'!$C$5/'계산기'!$C$7,PMT('계산기'!$C$12,'계산기'!$C$7,-'계산기'!$C$5))-D37,IF('계산기'!$C$8="원금균등",'계산기'!$C$5/'계산기'!$C$7,0)))) | F37: =IF(B37="","",D37+E37) | G37: =IF(B37="","",C37-E37)
B38: =IF(33<='계산기'!$C$7,33,"") | C38: =IF(B38="","",G37) | D38: =IF(B38="","",C38*'계산기'!$C$12) | E38: =IF(B38="","",IF(B38='계산기'!$C$7,C38,IF('계산기'!$C$8="원리금균등",IF('계산기'!$C$12=0,'계산기'!$C$5/'계산기'!$C$7,PMT('계산기'!$C$12,'계산기'!$C$7,-'계산기'!$C$5))-D38,IF('계산기'!$C$8="원금균등",'계산기'!$C$5/'계산기'!$C$7,0)))) | F38: =IF(B38="","",D38+E38) | G38: =IF(B38="","",C38-E38)
B39: =IF(34<='계산기'!$C$7,34,"") | C39: =IF(B39="","",G38) | D39: =IF(B39="","",C39*'계산기'!$C$12) | E39: =IF(B39="","",IF(B39='계산기'!$C$7,C39,IF('계산기'!$C$8="원리금균등",IF('계산기'!$C$12=0,'계산기'!$C$5/'계산기'!$C$7,PMT('계산기'!$C$12,'계산기'!$C$7,-'계산기'!$C$5))-D39,IF('계산기'!$C$8="원금균등",'계산기'!$C$5/'계산기'!$C$7,0)))) | F39: =IF(B39="","",D39+E39) | G39: =IF(B39="","",C39-E39)
B40: =IF(35<='계산기'!$C$7,35,"") | C40: =IF(B40="","",G39) | D40: =IF(B40="","",C40*'계산기'!$C$12) | E40: =IF(B40="","",IF(B40='계산기'!$C$7,C40,IF('계산기'!$C$8="원리금균등",IF('계산기'!$C$12=0,'계산기'!$C$5/'계산기'!$C$7,PMT('계산기'!$C$12,'계산기'!$C$7,-'계산기'!$C$5))-D40,IF('계산기'!$C$8="원금균등",'계산기'!$C$5/'계산기'!$C$7,0)))) | F40: =IF(B40="","",D40+E40) | G40: =IF(B40="","",C40-E40)
B41: =IF(36<='계산기'!$C$7,36,"") | C41: =IF(B41="","",G40) | D41: =IF(B41="","",C41*'계산기'!$C$12) | E41: =IF(B41="","",IF(B41='계산기'!$C$7,C41,IF('계산기'!$C$8="원리금균등",IF('계산기'!$C$12=0,'계산기'!$C$5/'계산기'!$C$7,PMT('계산기'!$C$12,'계산기'!$C$7,-'계산기'!$C$5))-D41,IF('계산기'!$C$8="원금균등",'계산기'!$C$5/'계산기'!$C$7,0)))) | F41: =IF(B41="","",D41+E41) | G41: =IF(B41="","",C41-E41)
B42: =IF(37<='계산기'!$C$7,37,"") | C42: =IF(B42="","",G41) | D42: =IF(B42="","",C42*'계산기'!$C$12) | E42: =IF(B42="","",IF(B42='계산기'!$C$7,C42,IF('계산기'!$C$8="원리금균등",IF('계산기'!$C$12=0,'계산기'!$C$5/'계산기'!$C$7,PMT('계산기'!$C$12,'계산기'!$C$7,-'계산기'!$C$5))-D42,IF('계산기'!$C$8="원금균등",'계산기'!$C$5/'계산기'!$C$7,0)))) | F42: =IF(B42="","",D42+E42) | G42: =IF(B42="","",C42-E42)
...
